Workbook

Sheet Diagrama de clases
A2: En esta hoja se ubica la imagen del modelo, asegurando que sea clara y legible

Sheet Clases
A1: Clase | B1: Estereotipo | C1: Desripción
A2: Producto | B2: class | C2: Clase que representa un producto del sistema, incluyendo su identificación, precio, estado y relaciones con categorías, unidades de medida, ventas, producción y abastecimiento.
A3: Categoria | B3: class | C3: Clase que representa la categoría a la que pertenecen los productos del sistema, permitiendo su clasificación y organización.
A4: UnidadMedida | B4: class | C4: Clase que representa la unidad de medida utilizada para cuantificar los productos del sistema.
A5: EstadoUsuario | B5: class | C5: Clase que representa el estado en el que se encuentra un usuario del sistema.
A6: Rol | B6: class | C6: Clase que representa el rol que puede tener un usuario dentro del sistema, definiendo sus permisos y nivel de acceso.
A7: Usuario | B7: class | C7: Clase que representa un usuario del sistema con su información personal, credenciales de acceso y relaciones con rol y estado
A8: Persona | B8: class | C8: Clase que representa una persona en el sistema con su información personal básica como nombres, apellidos y datos de contacto.
A9: Cliente | B9: class | C9: Clase que representa un cliente del sistema, extendiendo la información de persona con datos específicos de cliente.
A10: TipoIdentificacion | B10: class | C10: Clase que representa el tipo de identificación que puede tener una persona en el sistema (Cédula, Pasaporte, NIT, etc.).
A11: Venta | B11: class | C11: Clase que representa una venta realizada en el sistema, incluyendo información del cliente, estado, total y fecha de la transacción.
A12: Sede | B12: class | C12: Clase que representa una sede o sucursal del sistema de la bloquera, donde se realizan las operaciones comerciales.
... A21: StockSede | B21: class | C21: Clase que representa el inventario de stock de productos en una sede específica, permitiendo el control de existencias por ubicación.

Sheet Producto
A1: <-Volver al inicio
A2: =Clases!$A$1 -> Clase | B2: =Clases!A2 -> Producto
A3: =Clases!$B$1 -> Estereotipo | B3: =Clases!B2 -> class
A4: =Clases!$C$1 -> Desripción | B4: =Clases!C2 -> Clase que representa un producto del sistema, incluyendo su identificación, precio, estado y relaciones con categorías, unidades de medida, ventas, producción y abastecimiento.
A5: Modificador acceso: | B5: default
A6: Tipo clase: | B6: no final
A7: Relaciones
A8: Relación | B8: Tipo relación | E8: Estructura
A9: Necesita de | B9: Asociación | E9: =Categoria!B2 -> Categoria
A10: Es usada por | B10: Asociación | E10: UnidadMedida
A11: Es usada por | B11: Asociación | E11: =DetalleVenta!B2 -> DetalleVenta
A12: Es usada por | B12: Asociación | E12: Venta
A13: Es usada por | B13: Asociación | E13: Insumo
A14: Es usada por | B14: Asociación | E14: StockSede
A15: Es usada por | B15: Asociación | E15: DetalleAbastecimiento
A16: Atributos
A17: Modificador de aceso | B17: Nombre | C17: Tipo de dato | E17: Tipo modificación atributo | F17: Tipo acceso atributo | G17: Valor por defecto | J17: Descripción atributo
C18: Tipo de dato | D18: ¿Cuál?
A19: private | B19: idProducto | C19: long/Long | E19: no final | F19: no static | J19: Identificador único del producto
A20: private | B20: nombre | C20: String | E20: no final | F20: no static | J20: Nombre del producto
A21: private | B21: precio | C21: Otro | D21: BigDecimal | E21: no final | F21: no static | J21: Precio de venta del producto
A22: private | B22: estadoProducto | C22: Otro | D22: EstadoProducto | E22: no final | F22: no static | J22: Estado actual del producto (activo/inactivo)
A23: private | B23: categoria | C23: Otro | D23: Categoria | E23: no final | F23: no static | J23: Categoría a la que pertenece el producto
A24: private | B24: unidadMedida | C24: Otro | D24: UnidadMedida | E24: no final | F24: no static | J24: Unidad de medida asociada al producto
A25: Constructores
A26: Modificador de aceso | B26: Nombre | C26: Tipo constructor | D26: Descripción | E26: Parámetros | M26: Excepciones
E27: Nombre | F27: Tipo de dato | G27: ¿Cuál? | H27: Tipo parámetro | I27: Tipo modificación atributo | J27: Descripción
A28: public | B28: =B2 -> Producto | C28: Defecto | D28: Constructor por defecto requerido por JPA | E28: nombre | F28: String | H28: Por valor | I28: no final | J28: Nombre del producto | M28: —
A29: public | E29: precio | F29: Otro | G29: BigDecimal | H29: Por valor | I29: no final | J29: Precio del producto | M29: —
A30: public | C30: Parametrizado | D30: Constructor que inicializa los datos principales del producto | E30: categoria | F30: Otro | G30: Categoria | H30: Por valor | I30: no final | J30: Categoría asociada | M30: —
A31: public | E31: unidadMedida | F31: Otro | G31: UnidadMedida | H31: Por valor | I31: no final | J31: Unidad de medida | M31: —
A32: Métodos accesores
A33: Modificador de aceso | B33: Nombre | C33: Tipo método accesor | D33: Tipo modificación método | E33: Descripción | F33: Parámetros | L33: Tipo dato de retorno | N33: Excepciones
F34: Nombre | G34: Tipo de dato | H34: ¿Cuál? | I34: Tipo parámetro | J34: Tipo modificación atributo | K34: Descripción | L34: Tipo de dato | M34: ¿Cuál?
A35: public | B35: getIdProducto | C35: getter | D35: no final | E35: Obtiene el identificador del producto | G35: long/Long | L35: long/Long
A36: public | B36: getNombre | C36: getter | D36: no final | E36: Obtiene el nombre del producto | G36: short/Short | I36: Por valor | J36: no final
A37: public | B37: setNombre | C37: setter | D37: no final | E37: Asigna el nombre del producto
A38: public | B38: getPrecio | C38: getter | D38: no final | E38: Obtiene el precio del producto
A39: public | B39: setPrecio | C39: setter | D39: no final | E39: Asigna el precio del producto
A40: Métodos
...

Sheet Categoria
A1: <-Volver al inicio
A2: =Clases!$A$1 -> Clase | B2: =Clases!A3 -> Categoria
A3: =Clases!$B$1 -> Estereotipo | B3: =Clases!A4 -> UnidadMedida
A4: =Clases!$C$1 -> Desripción | B4: =Clases!C3 -> Clase que representa la categoría a la que pertenecen los productos del sistema, permitiendo su clasificación y organización.
A5: Modificador acceso: | B5: default
A6: Tipo clase: | B6: no final
A7: Relaciones
A8: Relación | B8: Tipo relación | E8: Estructura
A9: Es usada por | B9: Asociación | E9: =Producto!B2 -> Producto
A10: Atributos
A11: Modificador de aceso | B11: Nombre | C11: Tipo de dato | E11: Tipo modificación atributo | F11: Tipo acceso atributo | G11: Valor por defecto | J11: Descripción atributo
C12: Tipo de dato | D12: ¿Cuál?
A13: private | B13: id | C13: long/Long | E13: no final | F13: no static | J13: Identificador único de la categoría
A14: private | B14: nombre | C14: String | E14: no final | F14: no static | J14: Nombre de la categoría
A15: Constructores
A16: Modificador de aceso | B16: Nombre | C16: Tipo constructor | D16: Descripción | E16: Parámetros | M16: Excepciones
E17: Nombre | F17: Tipo de dato | G17: ¿Cuál? | H17: Tipo parámetro | I17: Tipo modificación atributo | J17: Descripción
A18: public | B18: =B2 -> Categoria | C18: Defecto | D18: Constructor por defecto que inicializa una nueva instancia de UnidadMedida sin parámetros | E18: id | F18: long/Long | H18: Por valor | I18: no final | J18: Parámetro que representa el identificador único de la unidad de medida
A19: public | B19: =B2 -> Categoria | C19: Parametrizado | D19: Constructor parametrizado que inicializa una UnidadMedida con sus atributos id y nombre | E19: nombre | F19: String | H19: Por valor | I19: no final | J19: Parámetro que representa el nombre de la unidad de medida
A20: Métodos accesores
A21: Modificador de aceso | B21: Nombre | C21: Tipo método accesor | D21: Tipo modificación método | E21: Descripción | F21: Parámetros | L21: Tipo dato de retorno | N21: Excepciones
F22: Nombre | G22: Tipo de dato | H22: ¿Cuál? | I22: Tipo parámetro | J22: Tipo modificación atributo | K22: Descripción | L22: Tipo de dato | M22: ¿Cuál?
A23: public | B23: getId | C23: getter | D23: no final | E23: Método encargado de obtener el valor del atributo id | F23: id | G23: long/Long | I23: Por valor | J23: no final | K23: Parámetro que representa el identificador único de la unidad de medida | L23: long/Long
A24: public | B24: getNombre | C24: getter | D24: no final | E24: Método encargado de obtener el valor del atributo nombre | F24: nombre | G24: String | I24: Por valor | J24: no final | K24: Parámetro que representa el nombre de la unidad de medida | L24: String
A25: public | B25: setNombre | C25: setter | D25: no final | E25: Método encargado de colocar el valor al atributo nombre
A26: Métodos
A27: Modificador de aceso | B27: Nombre | C27: Tipo acceso método | D27: Tipo modificación método | E27: Descripción | F27: Parámetros | L27: Tipo dato de retorno | N27: Excepciones
F28: Nombre | G28: Tipo de dato | H28: ¿Cuál? | I28: Tipo parámetro | J28: Tipo modificación atributo | K28: Descripción | L28: Tipo de dato | M28: ¿Cuál?
A29: public | B29: obtenerNombre | C29: no static | D29: no final | E29: Método encargado de obtener el nombre de la unidad de medida

Sheet UnidadMedida
A1: <-Volver al inicio
A2: =Clases!$A$1 -> Clase | B2: =Clases!A4 -> UnidadMedida
A3: =Clases!$B$1 -> Estereotipo | B3: =Clases!B4 -> class
A4: =Clases!$C$1 -> Desripción | B4: =Clases!C4 -> Clase que representa la unidad de medida utilizada para cuantificar los productos del sistema.
A5: Modificador acceso: | B5: default
A6: Tipo clase: | B6: no final
A7: Relaciones
A8: Relación | B8: Tipo relación | E8: Estructura
A9: Es usada por | B9: Asociación | E9: =Producto!B2 -> Producto
A10: Atributos
A11: Modificador de aceso | B11: Nombre | C11: Tipo de dato | E11: Tipo modificación atributo | F11: Tipo acceso atributo | G11: Valor por defecto | J11: Descripción atributo
C12: Tipo de dato | D12: ¿Cuál?
A13: private | B13: id | C13: long/Long | E13: no final | F13: no static | J13: Identificador único de la unidad de medida
A14: private | B14: nombre | C14: String | E14: no final | F14: no static | J14: Nombre de la unidad de medida
A15: Constructores
A16: Modificador de aceso | B16: Nombre | C16: Tipo constructor | D16: Descripción | E16: Parámetros | M16: Excepciones
E17: Nombre | F17: Tipo de dato | G17: ¿Cuál? | H17: Tipo parámetro | I17: Tipo modificación atributo | J17: Descripción
A18: public | B18: =B2 -> UnidadMedida | C18: Defecto | D18: Constructor por defecto que inicializa una nueva instancia de Categoria sin parámetros | E18: id | F18: long/Long | H18: Por valor | I18: no final | J18: Parámetro que representa el identificador único de la categoría
A19: public | B19: =B2 -> UnidadMedida | C19: Parametrizado | D19: Constructor parametrizado que inicializa una Categoria con sus atributos id y nombre | E19: nombre | F19: String | H19: Por valor | I19: no final | J19: Parámetro que representa el nombre de la categoría
A20: Métodos accesores
A21: Modificador de aceso | B21: Nombre | C21: Tipo método accesor | D21: Tipo modificación método | E21: Descripción | F21: Parámetros | L21: Tipo dato de retorno | N21: Excepciones
F22: Nombre | G22: Tipo de dato | H22: ¿Cuál? | I22: Tipo parámetro | J22: Tipo modificación atributo | K22: Descripción | L22: Tipo de dato | M22: ¿Cuál?
A23: public | B23: getId | C23: getter | D23: no final | E23: Método encargado de obtener el valor del atributo id | F23: id | G23: long/Long | I23: Por valor | J23: no final | K23: Parámetro que representa el identificador a asignar al atributo id
A24: public | B24: getNombre | C24: setter | D24: no final | E24: Método encargado de obtener el valor del atributo nombre | F24: nombre | G24: String | I24: Por valor | J24: no final | K24: Parámetro que representa el nombre a asignar al atributo nombre
A25: public | B25: setNombre | C25: setter | D25: no final | E25: Método encargado de colocar el valor al atributo nombre
A26: Métodos
A27: Modificador de aceso | B27: Nombre | C27: Tipo acceso método | D27: Tipo modificación método | E27: Descripción | F27: Parámetros | L27: Tipo dato de retorno | N27: Excepciones
F28: Nombre | G28: Tipo de dato | H28: ¿Cuál? | I28: Tipo parámetro | J28: Tipo modificación atributo | K28: Descripción | L28: Tipo de dato | M28: ¿Cuál?
A29: public | B29: retornarNuevoNombre | C29: no static | D29: no final | E29: Método encargado de retornar un nuevo nombre para la categoría basado en el parámetro recibido | F29: nombre | G29: String | I29: Por valor | J29: no final | K29: Parámetro que representa el nuevo nombre de la categoría | L29: String

Sheet EstadoUsuario
A1: <-Volver al inicio
A2: =Clases!$A$1 -> Clase | B2: =Clases!A5 -> EstadoUsuario
A3: =Clases!$B$1 -> Estereotipo | B3: =Clases!B5 -> class
A4: =Clases!$C$1 -> Desripción | B4: =Clases!C5 -> Clase que representa el estado en el que se encuentra un usuario del sistema.
A5: Modificador acceso: | B5: default
A6: Tipo clase: | B6: no final
A7: Relaciones
A8: Relación | B8: Tipo relación | E8: Estructura
A9: Es usada por | B9: Asociación | E9: Usuario
A10: Atributos
A11: Modificador de aceso | B11: Nombre | C11: Tipo de dato | E11: Tipo modificación atributo | F11: Tipo acceso atributo | G11: Valor por defecto | J11: Descripción atributo
C12: Tipo de dato | D12: ¿Cuál?
A13: private | B13: id | C13: long/Long | E13: no final | F13: no static | J13: Identificador único del estado de usuario
A14: private | B14: nombre | C14: String | E14: no final | F14: no static | J14: Nombre del estado de usuario
A15: Constructores
A16: Modificador de aceso | B16: Nombre | C16: Tipo constructor | D16: Descripción | E16: Parámetros | M16: Excepciones
E17: Nombre | F17: Tipo de dato | G17: ¿Cuál? | H17: Tipo parámetro | I17: Tipo modificación atributo | J17: Descripción
A18: public | B18: =B2 -> EstadoUsuario | C18: Defecto | D18: Constructor por defecto que inicializa una nueva instancia de EstadoUsuario sin parámetros
A19: public | B19: =B2 -> EstadoUsuario | C19: Parametrizado | D19: Constructor parametrizado que inicializa un EstadoUsuario con sus atributos id y nombre | E19: id | F19: long/Long | H19: Por valor | I19: no final | J19: Parámetro que representa el identificador único del estado de usuario
E20: nombre | F20: String | J20: Parámetro que representa el nombre del estado de usuario
A21: Métodos accesores
A22: Modificador de aceso | B22: Nombre | C22: Tipo método accesor | D22: Tipo modificación método | E22: Descripción | F22: Parámetros | L22: Tipo dato de retorno | N22: Excepciones
F23: Nombre | G23: Tipo de dato | H23: ¿Cuál? | I23: Tipo parámetro | J23: Tipo modificación atributo | K23: Descripción | L23: Tipo de dato | M23: ¿Cuál?
A24: public | B24: getId | C24: getter | D24: no final | E24: Método encargado de obtener el valor del atributo id | F24: id | G24: long/Long | I24: Por valor | J24: no final | K24: Parámetro que representa el identificador a asignar al atributo id | L24: long/Long
A25: public | B25: setId | C25: setter | D25: no final | E25: Método encargado de colocar el valor al atributo id
A26: public | B26: getNombre | C26: getter | D26: no final | E26: Método encargado de obtener el valor del atributo nombre | F26: nombre | G26: String | K26: Parámetro que representa el nombre a asignar al atributo nombre | L26: String
A27: public | B27: setNombre | C27: setter | D27: no final | E27: Método encargado de colocar el valor al atributo nombre
A28: Métodos
A29: Modificador de aceso | B29: Nombre | C29: Tipo acceso método | D29: Tipo modificación método | E29: Descripción | F29: Parámetros | L29: Tipo dato de retorno | N29: Excepciones
F30: Nombre | G30: Tipo de dato | H30: ¿Cuál? | I30: Tipo parámetro | J30: Tipo modificación atributo | K30: Descripción | L30: Tipo de dato | M30: ¿Cuál?
A31: public | B31: obtenerNombre | C31: no static | D31: no final | E31: Método encargado de obtener el nombre del estado de usuario | L31: String

Sheet Rol
A1: <-Volver al inicio
A2: =Clases!$A$1 -> Clase | B2: =Clases!A6 -> Rol
A3: =Clases!$B$1 -> Estereotipo | B3: =Clases!B6 -> class
A4: =Clases!$C$1 -> Desripción | B4: =Clases!C6 -> Clase que representa el rol que puede tener un usuario dentro del sistema, definiendo sus permisos y nivel de acceso.
A5: Modificador acceso: | B5: default
A6: Tipo clase: | B6: no final
A7: Relaciones
A8: Relación | B8: Tipo relación | E8: Estructura
A9: Es usada por | B9: Asociación | E9: Usuario
A10: Atributos
A11: Modificador de aceso | B11: Nombre | C11: Tipo de dato | E11: Tipo modificación atributo | F11: Tipo acceso atributo | G11: Valor por defecto | J11: Descripción atributo
C12: Tipo de dato | D12: ¿Cuál?
A13: private | B13: id | C13: long/Long | E13: no final | F13: no static | J13: Identificador único del rol
A14: private | B14: nombre | C14: String | E14: no final | F14: no static | J14: Nombre del rol
A15: Constructores
A16: Modificador de aceso | B16: Nombre | C16: Tipo constructor | D16: Descripción | E16: Parámetros | M16: Excepciones
E17: Nombre | F17: Tipo de dato | G17: ¿Cuál? | H17: Tipo parámetro | I17: Tipo modificación atributo | J17: Descripción
A18: public | B18: =B2 -> Rol | C18: Defecto | D18: Constructor por defecto que inicializa una nueva instancia de Rol sin parámetros
A19: public | B19: =B2 -> Rol | C19: Parametrizado | D19: Constructor parametrizado que inicializa un Rol con sus atributos id y nombre | E19: id | F19: long/Long | H19: Por valor | I19: no final | J19: Parámetro que representa el identificador único del rol
E20: nombre | F20: String | H20: Por valor | I20: no final | J20: Parámetro que representa el nombre del rol
A21: Métodos accesores
A22: Modificador de aceso | B22: Nombre | C22: Tipo método accesor | D22: Tipo modificación método | E22: Descripción | F22: Parámetros | L22: Tipo dato de retorno | N22: Excepciones
F23: Nombre | G23: Tipo de dato | H23: ¿Cuál? | I23: Tipo parámetro | J23: Tipo modificación atributo | K23: Descripción | L23: Tipo de dato | M23: ¿Cuál?
A24: public | B24: getId | C24: getter | D24: no final | E24: Método encargado de obtener el valor del atributo id | F24: id | G24: long/Long | I24: Por valor | J24: no final | K24: Parámetro que representa el identificador a asignar al atributo id | L24: long/Long
A25: public | B25: setId | C25: setter | D25: no final | E25: Método encargado de colocar el valor al atributo id
A26: public | B26: getNombre | C26: getter | D26: no final | E26: Método encargado de obtener el valor del atributo nombre | F26: nombre | G26: String | K26: Parámetro que representa el nombre a asignar al atributo nombre | L26: String
A27: public | B27: setNombre | C27: setter | D27: no final | E27: Método encargado de colocar el valor al atributo nombre
A28: Métodos
A29: Modificador de aceso | B29: Nombre | C29: Tipo acceso método | D29: Tipo modificación método | E29: Descripción | F29: Parámetros | L29: Tipo dato de retorno | N29: Excepciones
F30: Nombre | G30: Tipo de dato | H30: ¿Cuál? | I30: Tipo parámetro | J30: Tipo modificación atributo | K30: Descripción | L30: Tipo de dato | M30: ¿Cuál?
A31: public | B31: obtenerNombre | C31: no static | D31: no final | E31: Método encargado de obtener el nombre del rol | L31: String

Sheet Valores
A1: Estereotipo | B1: Relación | C1: Tipo relación | D1: Modificador acceso clase top level | E1: Tipo estructura | F1: Modificador acceso clase top level | G1: Tipo de dato | H1: Tipo acceso | I1: Tipo constructor | J1: Tipo parámetro | K1: Tipo método accesor | L1: Tipo de dato retorno método
A2: class | B2: Necesita de | C2: Asociación | D2: public | E2: final | F2: private | G2: byte/Byte | H2: static | I2: Defecto | J2: Por valor | K2: getter | L2: void
A3: abstract class | B3: Es usada por | C3: Agregación | D3: default | E3: no final | F3: protected | G3: short/Short | H3: no static | I3: Parametrizado | J3: Por referencia | K3: setter | L3: byte/Byte
A4: interface | C4: Composición | F4: default | G4: int/Integer | L4: short/Short
A5: enum | C5: Dependencia | F5: public | G5: long/Long | L5: int/Integer
A6: record | C6: Herencia | G6: float/Float | L6: long/Long
C7: Realización | G7: double/Double | L7: float/Float
G8: char/Character | L8: double/Double
G9: boolean/Boolean | L9: char/Character
G10: String | L10: boolean/Boolean
G11: Date | L11: String
G12: Otro | L12: Date
L13: Otro

Sheet Usuario
A1: <-Volver al inicio
A2: =Clases!$A$1 -> Clase | B2: =Clases!A7 -> Usuario
A3: =Clases!$B$1 -> Estereotipo | B3: =Clases!B7 -> class
A4: =Clases!$C$1 -> Desripción | B4: =Clases!C7 -> Clase que representa un usuario del sistema con su información personal, credenciales de acceso y relaciones con rol y estado
A5: Modificador acceso: | B5: default
A6: Tipo clase: | B6: no final
A7: Relaciones
A8: Relación | B8: Tipo relación | E8: Estructura
A9: Es usada por | B9: Asociación | E9: Rol
A10: Es usada por | B10: Asociación | E10: EstadoUsuario
A11: Es usada por | B11: Asociación | E11: Venta
A12: Atributos
A13: Modificador de aceso | B13: Nombre | C13: Tipo de dato | E13: Tipo modificación atributo | F13: Tipo acceso atributo | G13: Valor por defecto | J13: Descripción atributo
C14: Tipo de dato | D14: ¿Cuál?
A15: private | B15: id | C15: long/Long | E15: no final | F15: no static | J15: Identificador único del usuario
A16: private | B16: username | C16: String | E16: no final | F16: no static | J16: Nombre de usuario para acceso al sistema
A17: private | B17: hashedPassword | C17: String | E17: no final | F17: no static | J17: Contraseña hasheada del usuario
A18: private | B18: role | C18: Otro | D18: Role | E18: no final | F18: no static | J18: Rol asignado al usuario
A19: private | B19: sede | C19: Otro | D19: Sede | E19: no final | F19: no static | J19: Sede a la que pertenece el usuario
A20: private | B20: isEnabled | C20: boolean/Boolean | E20: no final | F20: no static | J20: Indica si el usuario está habilitado en el sistema
A21: Constructores
A22: Modificador de aceso | B22: Nombre | C22: Tipo constructor | D22: Descripción | E22: Parámetros | M22: Excepciones
E23: Nombre | F23: Tipo de dato | G23: ¿Cuál? | H23: Tipo parámetro | I23: Tipo modificación atributo | J23: Descripción
A24: public | B24: =B2 -> Usuario | C24: Defecto | D24: Constructor por defecto que inicializa una nueva instancia de Usuario sin parámetros | E24: id | F24: long/Long | H24: Por valor | I24: no final | J24: Parámetro que representa el identificador único del usuario
A25: public | B25: =B2 -> Usuario | C25: Parametrizado | D25: Constructor parametrizado que inicializa un Usuario con todos sus atributos | E25: username | F25: String | H25: Por valor | I25: no final | J25: Parámetro que representa el nombre de usuario
E26: hashedPassword | F26: String | H26: Por valor | I26: no final | J26: Parámetro que representa la contraseña hasheada
E27: role | F27: Otro | G27: Role | H27: Por valor | I27: no final | J27: Parámetro que representa el rol del usuario
E28: sede | F28: Otro | G28: Sede | H28: Por valor | I28: no final | J28: Parámetro que representa la sede del usuario
E29: isEnabled | F29: boolean/Boolean | H29: Por valor | I29: no final | J29: Parámetro que indica si el usuario está habilitado
A30: Métodos accesores
A31: Modificador de aceso | B31: Nombre | C31: Tipo método accesor | D31: Tipo modificación método | E31: Descripción | F31: Parámetros | L31: Tipo dato de retorno | N31: Excepciones
F32: Nombre | G32: Tipo de dato | H32: ¿Cuál? | I32: Tipo parámetro | J32: Tipo modificación atributo | K32: Descripción | L32: Tipo de dato | M32: ¿Cuál?
A33: public | B33: getId | C33: getter | D33: no final | E33: Método encargado de obtener el valor del atributo id | F33: id | G33: long/Long | I33: Por valor | J33: no final | K33: Parámetro que representa el identificador a asignar al atributo id | L33: long/Long
A34: public | B34: setId | C34: setter | D34: no final | E34: Método encargado de colocar el valor al atributo id | I34: Por valor
A35: public | B35: getUsername | C35: getter | D35: no final | E35: Método encargado de obtener el valor del atributo username | F35: username | G35: String | I35: Por valor | K35: Parámetro que representa el nombre de usuario a asignar | L35: String
A36: public | B36: setUsername | C36: setter | D36: no final | E36: Método encargado de colocar el valor al atributo username | I36: Por valor
A37: public | B37: getHashedPassword | C37: getter | D37: no final | E37: Método encargado de obtener el valor del atributo hashedPassword | F37: hashedPassword | G37: String | I37: Por valor | K37: Parámetro que representa la contraseña hasheada a asignar | L37: String
A38: public | B38: setHashedPassword | C38: setter | D38: no final | E38: Método encargado de colocar el valor al atributo hashedPassword | I38: Por valor
A39: public | B39: getRole | C39: getter | D39: no final | E39: Método encargado de obtener el valor del atributo role | F39: role | G39: Otro | H39: Role | I39: Por valor | K39: Parámetro que representa el rol a asignar al usuario | L39: Otro | M39: Role
A40: public | B40: setRole | C40: setter | D40: no final | E40: Método encargado de colocar el valor al atributo role | I40: Por valor
...

Sheet Persona
A1: <-Volver al inicio
A2: =Clases!$A$1 -> Clase | B2: =Clases!A8 -> Persona
A3: =Clases!$B$1 -> Estereotipo | B3: =Clases!B8 -> class
A4: =Clases!$C$1 -> Desripción | B4: =Clases!C8 -> Clase que representa una persona en el sistema con su información personal básica como nombres, apellidos y datos de contacto.
A5: Modificador acceso: | B5: default
A6: Tipo clase: | B6: no final
A7: Relaciones
A8: Relación | B8: Tipo relación | E8: Estructura
A9: Es usada por | B9: Asociación | E9: Cliente
A10: Necesita de | B10: Asociación | E10: TipoIdentificacion
A11: Atributos
A12: Modificador de aceso | B12: Nombre | C12: Tipo de dato | E12: Tipo modificación atributo | F12: Tipo acceso atributo | G12: Valor por defecto | J12: Descripción atributo
C13: Tipo de dato | D13: ¿Cuál?
A14: private | B14: id | C14: long/Long | E14: no final | F14: no static | J14: Identificador único de la persona
A15: private | B15: firstName | C15: String | E15: no final | F15: no static | J15: Primer nombre de la persona
A16: private | B16: lastName | C16: String | E16: no final | F16: no static | J16: Apellido de la persona
A17: private | B17: email | C17: String | E17: no final | F17: no static | J17: Correo electrónico de la persona
A18: Constructores
A19: Modificador de aceso | B19: Nombre | C19: Tipo constructor | D19: Descripción | E19: Parámetros | M19: Excepciones
E20: Nombre | F20: Tipo de dato | G20: ¿Cuál? | H20: Tipo parámetro | I20: Tipo modificación atributo | J20: Descripción
A21: public | B21: =B2 -> Persona | C21: Defecto | D21: Constructor por defecto que inicializa una nueva instancia de Persona sin parámetros
A22: public | B22: =B2 -> Persona | C22: Parametrizado | D22: Constructor parametrizado que inicializa una Persona con todos sus atributos | E22: id | F22: long/Long | H22: Por valor | I22: no final | J22: Parámetro que representa el identificador único de la persona
E23: firstName | F23: String | H23: Por valor | I23: no final | J23: Parámetro que representa el primer nombre de la persona
E24: lastName | F24: String | H24: Por valor | I24: no final | J24: Parámetro que representa el apellido de la persona
E25: email | F25: String | H25: Por valor | I25: no final | J25: Parámetro que representa el correo electrónico de la persona
A26: Métodos accesores
A27: Modificador de aceso | B27: Nombre | C27: Tipo método accesor | D27: Tipo modificación método | E27: Descripción | F27: Parámetros | L27: Tipo dato de retorno | N27: Excepciones
F28: Nombre | G28: Tipo de dato | H28: ¿Cuál? | I28: Tipo parámetro | J28: Tipo modificación atributo | K28: Descripción | L28: Tipo de dato | M28: ¿Cuál?
A29: public | B29: getId | C29: getter | D29: no final | E29: Método encargado de obtener el valor del atributo id | F29: id | G29: long/Long | I29: Por valor | J29: no final | K29: Parámetro que representa el identificador a asignar al atributo id | L29: long/Long
A30: public | B30: setId | C30: setter | D30: no final | E30: Método encargado de colocar el valor al atributo id | L30: void
A31: public | B31: getFirstName | C31: getter | D31: no final | E31: Método encargado de obtener el valor del atributo firstName | F31: firstName | G31: String | K31: Parámetro que representa el primer nombre a asignar | L31: String
A32: public | B32: setFirstName | C32: setter | D32: no final | E32: Método encargado de colocar el valor al atributo firstName | L32: void
A33: public | B33: getLastName | C33: getter | D33: no final | E33: Método encargado de obtener el valor del atributo lastName | F33: lastName | G33: String | K33: Parámetro que representa el apellido a asignar | L33: String
A34: public | B34: setLastName | C34: setter | D34: no final | E34: Método encargado de colocar el valor al atributo lastName | L34: void
A35: public | B35: getEmail | C35: getter | D35: no final | E35: Método encargado de obtener el valor del atributo email | F35: email | G35: String | K35: Parámetro que representa el correo electrónico a asignar | L35: String
A36: public | B36: setEmail | C36: setter | D36: no final | E36: Método encargado de colocar el valor al atributo email | L36: void
A37: Métodos
A38: Modificador de aceso | B38: Nombre | C38: Tipo acceso método | D38: Tipo modificación método | E38: Descripción | F38: Parámetros | L38: Tipo dato de retorno | N38: Excepciones
F39: Nombre | G39: Tipo de dato | H39: ¿Cuál? | I39: Tipo parámetro | J39: Tipo modificación atributo | K39: Descripción | L39: Tipo de dato | M39: ¿Cuál?
A40: public | B40: notificarPersona | C40: no static | D40: no final | E40: Método encargado de notificar a la persona | F40: email | G40: String | I40: Por valor | J40: no final | K40: Parámetro que representa el nuevo correo electrónico de contacto | L40: void
...

Sheet Cliente
A1: <-Volver al inicio
A2: =Clases!$A$1 -> Clase | B2: =Clases!A9 -> Cliente
A3: =Clases!$B$1 -> Estereotipo | B3: =Clases!B9 -> class
A4: =Clases!$C$1 -> Desripción | B4: =Clases!C9 -> Clase que representa un cliente del sistema, extendiendo la información de persona con datos específicos de cliente.
A5: Modificador acceso: | B5: default
A6: Tipo clase: | B6: no final
A7: Relaciones
A8: Relación | B8: Tipo relación | E8: Estructura
A9: Necesita de | B9: Asociación | E9: Persona
A10: Es usada por | B10: Asociación | E10: Venta
A11: Atributos
A12: Modificador de aceso | B12: Nombre | C12: Tipo de dato | E12: Tipo modificación atributo | F12: Tipo acceso atributo | G12: Valor por defecto | J12: Descripción atributo
C13: Tipo de dato | D13: ¿Cuál?
A14: private | B14: id | C14: long/Long | E14: no final | F14: no static | J14: Identificador único del cliente
A15: private | B15: activated | C15: String | E15: no final | F15: no static | J15: Estado de activación del cliente
A16: Constructores
A17: Modificador de aceso | B17: Nombre | C17: Tipo constructor | D17: Descripción | E17: Parámetros | M17: Excepciones
E18: Nombre | F18: Tipo de dato | G18: ¿Cuál? | H18: Tipo parámetro | I18: Tipo modificación atributo | J18: Descripción
A19: private | B19: =B2 -> Cliente | C19: Defecto | D19: Constructor por defecto que inicializa una nueva instancia de Cliente sin parámetros
A20: public | B20: =B2 -> Cliente | C20: Parametrizado | D20: Constructor parametrizado que inicializa un Cliente con todos sus atributos | E20: id | F20: long/Long | H20: Por valor | I20: no final | J20: Parámetro que representa el identificador único del cliente
E21: activated | F21: String | H21: Por valor | I21: no final | J21: Parámetro que representa el estado de activación del cliente
A22: Métodos accesores
A23: Modificador de aceso | B23: Nombre | C23: Tipo método accesor | D23: Tipo modificación método | E23: Descripción | F23: Parámetros | L23: Tipo dato de retorno | N23: Excepciones
F24: Nombre | G24: Tipo de dato | H24: ¿Cuál? | I24: Tipo parámetro | J24: Tipo modificación atributo | K24: Descripción | L24: Tipo de dato | M24: ¿Cuál?
A25: public | B25: getId | C25: getter | D25: no final | E25: Método encargado de obtener el valor del atributo id | L25: long/Long
A26: public | B26: setId | C26: setter | D26: no final | E26: Método encargado de colocar el valor al atributo id | F26: id | G26: long/Long | I26: Por valor | J26: no final | K26: Parámetro que representa el identificador a asignar al atributo id
A27: public | B27: getActivated | C27: getter | D27: no final | E27: Método encargado de obtener el valor del atributo activated | L27: String
A28: public | B28: setActivated | C28: setter | D28: no final | E28: Método encargado de colocar el valor al atributo activated | F28: activated | G28: String | I28: Por valor | J28: no final | K28: Parámetro que representa el estado de activación a asignar
A29: Métodos
A30: Modificador de aceso | B30: Nombre | C30: Tipo acceso método | D30: Tipo modificación método | E30: Descripción | F30: Parámetros | L30: Tipo dato de retorno | N30: Excepciones
F31: Nombre | G31: Tipo de dato | H31: ¿Cuál? | I31: Tipo parámetro | J31: Tipo modificación atributo | K31: Descripción | L31: Tipo de dato | M31: ¿Cuál?
A32: public | B32: updateActividadActividad | C32: no static | D32: no final | E32: Método encargado de actualizar la actividad del cliente | F32: actividad | G32: String | I32: Por valor | J32: no final | K32: Parámetro que representa la nueva actividad del cliente | L32: void
F33: string | G33: Date | I33: Por valor | J33: no final | K33: Parámetro adicional para la actualización de actividad | L33: void

Sheet TipoIdentificacion
A1: <-Volver al inicio
A2: =Clases!$A$1 -> Clase | B2: =Clases!A10 -> TipoIdentificacion
A3: =Clases!$B$1 -> Estereotipo | B3: =Clases!B10 -> class
A4: =Clases!$C$1 -> Desripción | B4: =Clases!C10 -> Clase que representa el tipo de identificación que puede tener una persona en el sistema (Cédula, Pasaporte, NIT, etc.).
A5: Modificador acceso: | B5: default
A6: Tipo clase: | B6: no final
A7: Relaciones
A8: Relación | B8: Tipo relación | E8: Estructura
A9: Es usada por | B9: Asociación | E9: Persona
A10: Atributos
A11: Modificador de aceso | B11: Nombre | C11: Tipo de dato | E11: Tipo modificación atributo | F11: Tipo acceso atributo | G11: Valor por defecto | J11: Descripción atributo
C12: Tipo de dato | D12: ¿Cuál?
A13: private | B13: id | C13: long/Long | E13: no final | F13: no static | J13: Identificador único del tipo de identificación
A14: private | B14: name | C14: String | E14: no final | F14: no static | J14: Nombre del tipo de identificación
A15: Constructores
A16: Modificador de aceso | B16: Nombre | C16: Tipo constructor | D16: Descripción | E16: Parámetros | M16: Excepciones
E17: Nombre | F17: Tipo de dato | G17: ¿Cuál? | H17: Tipo parámetro | I17: Tipo modificación atributo | J17: Descripción
A18: public | B18: =B2 -> TipoIdentificacion | C18: Defecto | D18: Constructor por defecto que inicializa una nueva instancia de TipoIdentificacion sin parámetros
A19: public | B19: =B2 -> TipoIdentificacion | C19: Parametrizado | D19: Constructor parametrizado que inicializa un TipoIdentificacion con sus atributos id y name | E19: id | F19: long/Long | H19: Por valor | I19: no final | J19: Parámetro que representa el identificador único del tipo de identificación
E20: name | F20: String | H20: Por valor | I20: no final | J20: Parámetro que representa el nombre del tipo de identificación
A21: Métodos accesores
A22: Modificador de aceso | B22: Nombre | C22: Tipo método accesor | D22: Tipo modificación método | E22: Descripción | F22: Parámetros | L22: Tipo dato de retorno | N22: Excepciones
F23: Nombre | G23: Tipo de dato | H23: ¿Cuál? | I23: Tipo parámetro | J23: Tipo modificación atributo | K23: Descripción | L23: Tipo de dato | M23: ¿Cuál?
A24: public | B24: getId | C24: getter | D24: no final | E24: Método encargado de obtener el valor del atributo id | L24: long/Long
A25: public | B25: setId | C25: setter | D25: no final | E25: Método encargado de colocar el valor al atributo id | F25: id | G25: long/Long | I25: Por valor | J25: no final | K25: Parámetro que representa el identificador a asignar al atributo id
A26: public | B26: getName | C26: getter | D26: no final | E26: Método encargado de obtener el valor del atributo name | L26: String
A27: public | B27: setName | C27: setter | D27: no final | E27: Método encargado de colocar el valor al atributo name | F27: Name | G27: String | I27: Por valor | J27: no final | K27: Parámetro que representa el nombre del tipo de identificación
A28: Métodos
A29: Modificador de aceso | B29: Nombre | C29: Tipo acceso método | D29: Tipo modificación método | E29: Descripción | F29: Parámetros | L29: Tipo dato de retorno | N29: Excepciones
F30: Nombre | G30: Tipo de dato | H30: ¿Cuál? | I30: Tipo parámetro | J30: Tipo modificación atributo | K30: Descripción | L30: Tipo de dato | M30: ¿Cuál?

Sheet Venta
A1: <-Volver al inicio
A2: =Clases!$A$1 -> Clase | B2: =Clases!A11 -> Venta
A3: =Clases!$B$1 -> Estereotipo | B3: =Clases!B11 -> class
A4: =Clases!$C$1 -> Desripción | B4: =Clases!C11 -> Clase que representa una venta realizada en el sistema, incluyendo información del cliente, estado, total y fecha de la transacción.
A5: Modificador acceso: | B5: default
A6: Tipo clase: | B6: no final
A7: Relaciones
A8: Relación | B8: Tipo relación | E8: Estructura
A9: Es usada por | B9: Asociación | E9: Cliente
A10: Tiene | B10: Asociación | E10: EstadoVenta
A11: Necesita de | B11: Composición | E11: DetalleVenta
A12: Atributos
A13: Modificador de aceso | B13: Nombre | C13: Tipo de dato | E13: Tipo modificación atributo | F13: Tipo acceso atributo | G13: Valor por defecto | J13: Descripción atributo
C14: Tipo de dato | D14: ¿Cuál?
A15: private | B15: id | C15: long/Long | E15: no final | F15: no static | J15: Identificador único de la venta
A16: private | B16: fechaVenta | C16: Date | D16: List<String> | E16: no final | F16: no static | J16: Fecha en que se realizó la venta
A17: private | B17: estado | C17: Otro | D17: EstadoVenta | E17: no final | F17: no static | J17: Estado actual de la venta
A18: private | B18: total | C18: Otro | D18: BigDecimal | E18: no final | F18: no static | J18: Monto total de la venta
A19: Constructores
A20: Modificador de aceso | B20: Nombre | C20: Tipo constructor | D20: Descripción | E20: Parámetros | M20: Excepciones
E21: Nombre | F21: Tipo de dato | G21: ¿Cuál? | H21: Tipo parámetro | I21: Tipo modificación atributo | J21: Descripción
A22: private | B22: =B2 -> Venta | C22: Defecto | D22: Constructor por defecto que inicializa una nueva instancia de Venta sin parámetros
A23: public | B23: =B2 -> Venta | C23: Parametrizado | D23: Constructor parametrizado que inicializa una Venta con todos sus atributos | E23: id | F23: long/Long | H23: Por valor | I23: no final | J23: Parámetro que representa el identificador único de la venta
A24: public | C24: Parametrizado | E24: fechaVenta | F24: Otro | G24: LocalDate | H24: Por valor | I24: no final | J24: Parámetro que representa la fecha de la venta
A25: public | C25: Parametrizado | E25: estado | F25: Otro | G25: EstadoVenta | H25: Por valor | I25: no final | J25: Parámetro que representa el estado de la venta
A26: public | C26: Parametrizado | E26: total | F26: Otro | G26: BigDecimal | H26: Por valor | I26: no final | J26: Parámetro que representa el total de la venta
A27: Métodos accesores
A28: Modificador de aceso | B28: Nombre | C28: Tipo método accesor | D28: Tipo modificación método | E28: Descripción | F28: Parámetros | L28: Tipo dato de retorno | N28: Excepciones
F29: Nombre | G29: Tipo de dato | H29: ¿Cuál? | I29: Tipo parámetro | J29: Tipo modificación atributo | K29: Descripción | L29: Tipo de dato | M29: ¿Cuál?
A30: public | B30: getId | C30: getter | D30: no final | E30: Método encargado de obtener el valor del atributo atributoUno | L30: long/Long
A31: public | B31: setId | C31: setter | D31: no final | E31: Método encargado de colocar el valor al atributo atributoUno | F31: id | G31: short/Short | I31: Por valor | J31: no final | K31: Parámetro que representa el identificador a asignar al atributo id
A32: public | B32: getFechaVenta | C32: getter | D32: no final | E32: Método encargado de obtener el valor del atributo atributoUno | L32: Otro | M32: LocalDate
A33: public | B33: setFechaVenta | C33: setter | D33: no final | E33: Método encargado de colocar el valor al atributo atributoUno | F33: fechaVenta | G33: Otro | H33: LocalDate | I33: Por valor | J33: no final | K33: Parámetro que representa la fecha a asignar al atributo fechaVenta
A34: public | B34: getEstado | C34: getter | D34: no final | E34: Método encargado de obtener el valor del atributo atributoUno | L34: Otro | M34: EstadoVenta
A35: public | B35: setEstado | C35: setter | D35: no final | E35: Método encargado de colocar el valor al atributo atributoUno | F35: estado | G35: Otro | H35: EstadoVenta | I35: Por valor | J35: no final | K35: Parámetro que representa el estado a asignar al atributo estado
A36: public | B36: getTotal | C36: getter | D36: no final | E36: Método encargado de obtener el valor del atributo total | L36: Otro | M36: BigDecimal
A37: public | B37: setTotal | C37: setter | D37: no final | E37: Método encargado de colocar el valor al atributo total | F37: total | G37: Otro | H37: BigDecimal | I37: Por valor | J37: no final | K37: Parámetro que representa el total a asignar al atributo total
A38: Métodos
A39: Modificador de aceso | B39: Nombre | C39: Tipo acceso método | D39: Tipo modificación método | E39: Descripción | F39: Parámetros | L39: Tipo dato de retorno | N39: Excepciones
F40: Nombre | G40: Tipo de dato | H40: ¿Cuál? | I40: Tipo parámetro | J40: Tipo modificación atributo | K40: Descripción | L40: Tipo de dato | M40: ¿Cuál?
...

Sheet Sede
A1: <-Volver al inicio
A2: =Clases!$A$1 -> Clase | B2: =Clases!A12 -> Sede
A3: =Clases!$B$1 -> Estereotipo | B3: =Clases!B12 -> class
A4: =Clases!$C$1 -> Desripción | B4: =Clases!C12 -> Clase que representa una sede o sucursal del sistema de la bloquera, donde se realizan las operaciones comerciales.
A5: Modificador acceso: | B5: default
A6: Tipo clase: | B6: no final
A7: Relaciones
A8: Relación | B8: Tipo relación | E8: Estructura
A9: Es usada por | B9: Asociación | E9: Usuario
A10: Atributos
A11: Modificador de aceso | B11: Nombre | C11: Tipo de dato | E11: Tipo modificación atributo | F11: Tipo acceso atributo | G11: Valor por defecto | J11: Descripción atributo
C12: Tipo de dato | D12: ¿Cuál?
A13: private | B13: id | C13: long/Long | E13: no final | F13: no static | J13: Identificador único de la sede
A14: private | B14: nombre | C14: String | E14: no final | F14: no static | J14: Nombre de la sede
A15: private | B15: direccion | C15: String | E15: no final | F15: no static | J15: Dirección física de la sede
A16: Constructores
A17: Modificador de aceso | B17: Nombre | C17: Tipo constructor | D17: Descripción | E17: Parámetros | M17: Excepciones
E18: Nombre | F18: Tipo de dato | G18: ¿Cuál? | H18: Tipo parámetro | I18: Tipo modificación atributo | J18: Descripción
A19: private | B19: =B2 -> Sede | C19: Defecto | D19: Constructor por defecto que inicializa una nueva instancia de Sede sin parámetros
A20: public | B20: =B2 -> Sede | C20: Parametrizado | D20: Constructor parametrizado que inicializa una Sede con todos sus atributos | E20: id | F20: long/Long | H20: Por valor | I20: no final | J20: Parámetro que representa el identificador único de la sede
A21: public | C21: Parametrizado | E21: nombre | F21: String | H21: Por valor | I21: no final | J21: Parámetro que representa el nombre de la sede
A22: public | C22: Parametrizado | E22: direccion | F22: String | H22: Por valor | I22: no final | J22: Parámetro que representa la dirección de la sede
A23: Métodos accesores
A24: Modificador de aceso | B24: Nombre | C24: Tipo método accesor | D24: Tipo modificación método | E24: Descripción | F24: Parámetros | L24: Tipo dato de retorno | N24: Excepciones
F25: Nombre | G25: Tipo de dato | H25: ¿Cuál? | I25: Tipo parámetro | J25: Tipo modificación atributo | K25: Descripción | L25: Tipo de dato | M25: ¿Cuál?
A26: public | B26: getId | C26: getter | D26: no final | E26: Método encargado de obtener el valor del atributo id | L26: long/Long
A27: public | B27: setId | C27: setter | D27: no final | E27: Método encargado de colocar el valor al atributo id | F27: id | G27: long/Long | I27: Por valor | J27: no final | K27: Parámetro que representa el identificador a asignar al atributo id
A28: public | B28: getNombre | C28: getter | D28: no final | E28: Método encargado de obtener el valor del atributo nombre | L28: String
A29: public | B29: setNombre | C29: setter | D29: no final | E29: Método encargado de colocar el valor al atributo nombre | F29: nombre | G29: String | I29: Por valor | J29: no final | K29: Parámetro que representa el nombre a asignar al atributo nombre
A30: public | B30: getDireccion | C30: getter | D30: no final | E30: Método encargado de obtener el valor del atributo direccion | L30: String
A31: public | B31: setDireccion | C31: setter | D31: no final | E31: Método encargado de colocar el valor al atributo direccion | F31: direccion | G31: String | I31: Por valor | J31: no final | K31: Parámetro que representa la dirección a asignar al atributo direccion
A32: Métodos
A33: Modificador de aceso | B33: Nombre | C33: Tipo acceso método | D33: Tipo modificación método | E33: Descripción | F33: Parámetros | L33: Tipo dato de retorno | N33: Excepciones
F34: Nombre | G34: Tipo de dato | H34: ¿Cuál? | I34: Tipo parámetro | J34: Tipo modificación atributo | K34: Descripción | L34: Tipo de dato | M34: ¿Cuál?
A35: public | B35: obtenerIdNombreNombreSede | C35: no static | D35: no final | E35: Método encargado de obtener el id y nombre de la sede | F35: nombre | G35: String | I35: Por valor | J35: no final | K35: Parámetro que representa el nombre de la sede | L35: String | N35: En caso de que el valor recibido por parámetro llegue vacío
A36: public | B36: recuperarDireccionNombreSede | C36: no static | D36: no final | E36: Método encargado de recuperar la dirección de la sede por su nombre | F36: nombreSede | G36: String | I36: Por valor | J36: no final | K36: Parámetro que representa el nombre de la sede para recuperar dirección | L36: String | N36: En caso de que el valor recibido por parámetro llegue vacío

Sheet DetalleVenta
A1: <-Volver al inicio
A2: =Clases!$A$1 -> Clase | B2: =Clases!A13 -> DetalleVenta
A3: =Clases!$B$1 -> Estereotipo | B3: =Clases!B13 -> class
A4: =Clases!$C$1 -> Desripción | B4: =Clases!C13 -> Clase que representa el detalle de una venta, conteniendo información sobre los productos vendidos, cantidades y precios.
A5: Modificador acceso: | B5: default
A6: Tipo clase: | B6: no final
A7: Relaciones
A8: Relación | B8: Tipo relación | E8: Estructura
A9: Necesita de | B9: Composición | E9: Venta
A10: Es usada por | B10: Asociación | E10: Producto
A11: Atributos
A12: Modificador de aceso | B12: Nombre | C12: Tipo de dato | E12: Tipo modificación atributo | F12: Tipo acceso atributo | G12: Valor por defecto | J12: Descripción atributo
C13: Tipo de dato | D13: ¿Cuál?
A14: private | B14: id | C14: long/Long | E14: no final | F14: no static | J14: Identificador único del detalle de venta
A15: private | B15: cantidad | C15: Otro | D15: BigDecimal | E15: no final | F15: no static | J15: Cantidad del producto vendido
A16: private | B16: precioUnitario | C16: Otro | D16: BigDecimal | E16: no final | F16: no static | J16: Precio unitario del producto al momento de la venta
A17: private | B17: subtotal | C17: Otro | D17: BigDecimal | E17: no final | F17: no static | J17: Subtotal del detalle (cantidad * precioUnitario)
A18: Constructores
A19: Modificador de aceso | B19: Nombre | C19: Tipo constructor | D19: Descripción | E19: Parámetros | M19: Excepciones
E20: Nombre | F20: Tipo de dato | G20: ¿Cuál? | H20: Tipo parámetro | I20: Tipo modificación atributo | J20: Descripción
A21: public | B21: =B2 -> DetalleVenta | C21: Defecto | D21: Constructor por defecto que inicializa una nueva instancia de DetalleVenta sin parámetros
A22: public | B22: =B2 -> DetalleVenta | C22: Parametrizado | D22: Constructor parametrizado que inicializa un DetalleVenta con todos sus atributos | E22: id | F22: long/Long | H22: Por valor | I22: no final | J22: Parámetro que representa el identificador único del detalle de venta
A23: public | C23: Parametrizado | E23: cantidad | F23: Otro | G23: BigDecimal | H23: Por valor | I23: no final | J23: Parámetro que representa la cantidad del producto
A24: public | C24: Parametrizado | E24: precioUnitario | F24: Otro | G24: BigDecimal | H24: Por valor | I24: no final | J24: Parámetro que representa el precio unitario del producto
A25: public | C25: Parametrizado | E25: subtotal | F25: Otro | G25: BigDecimal | H25: Por valor | I25: no final | J25: Parámetro que representa el subtotal del detalle
A26: Métodos accesores
A27: Modificador de aceso | B27: Nombre | C27: Tipo método accesor | D27: Tipo modificación método | E27: Descripción | F27: Parámetros | L27: Tipo dato de retorno | N27: Excepciones
F28: Nombre | G28: Tipo de dato | H28: ¿Cuál? | I28: Tipo parámetro | J28: Tipo modificación atributo | K28: Descripción | L28: Tipo de dato | M28: ¿Cuál?
A29: public | B29: getId | C29: getter | D29: no final | E29: Método encargado de obtener el valor del atributo id | L29: long/Long
A30: public | B30: setId | C30: setter | D30: no final | E30: Método encargado de colocar el valor al atributo id | F30: id | G30: long/Long | I30: Por valor | J30: no final | K30: Parámetro que representa el identificador a asignar al atributo id
A31: public | B31: getCantidad | C31: getter | D31: no final | E31: Método encargado de obtener el valor del atributo cantidad | L31: Otro | M31: BigDecimal
A32: public | B32: setCantidad | C32: setter | D32: no final | E32: Método encargado de colocar el valor al atributo cantidad | F32: cantidad | G32: Otro | H32: BigDecimal | I32: Por valor | J32: no final | K32: Parámetro que representa la cantidad a asignar al atributo cantidad
A33: public | B33: getPrecioUnitario | C33: getter | D33: no final | E33: Método encargado de obtener el valor del atributo precioUnitario | L33: Otro | M33: BigDecimal
A34: public | B34: setPrecioUnitario | C34: setter | D34: no final | E34: Método encargado de colocar el valor al atributo precioUnitario | F34: precioUnitario | G34: Otro | H34: BigDecimal | I34: Por valor | J34: no final | K34: Parámetro que representa el precio unitario a asignar
A35: public | B35: getSubtotal | C35: getter | D35: no final | E35: Método encargado de obtener el valor del atributo subtotal | L35: Otro | M35: BigDecimal
A36: public | B36: setSubtotal | C36: setter | D36: no final | E36: Método encargado de colocar el valor al atributo subtotal | F36: subtotal | G36: Otro | H36: BigDecimal | I36: Por valor | J36: no final | K36: Parámetro que representa el subtotal a asignar al atributo subtotal
A37: Métodos
A38: Modificador de aceso | B38: Nombre | C38: Tipo acceso método | D38: Tipo modificación método | E38: Descripción | F38: Parámetros | L38: Tipo dato de retorno | N38: Excepciones
F39: Nombre | G39: Tipo de dato | H39: ¿Cuál? | I39: Tipo parámetro | J39: Tipo modificación atributo | K39: Descripción | L39: Tipo de dato | M39: ¿Cuál?
A40: public | B40: obtenerSubtotal | C40: no static | D40: no final | E40: Método encargado de obtener el subtotal del detalle de venta | L40: Otro | M40: BigDecimal | N40: En caso de que el valor recibido por parámetro llegue vacío
...

Sheet Pago
A1: <-Volver al inicio
A2: =Clases!$A$1 -> Clase | B2: =Clases!A14 -> Pago
A3: =Clases!$B$1 -> Estereotipo | B3: =Clases!B14 -> class
A4: =Clases!$C$1 -> Desripción | B4: =Clases!C14 -> Clase que representa un pago realizado por el cliente, incluyendo información sobre el monto, fecha y método de pago utilizado.
A5: Modificador acceso: | B5: default
A6: Tipo clase: | B6: no final
A7: Relaciones
A8: Relación | B8: Tipo relación | E8: Estructura
A9: Necesita de | B9: Asociación | E9: Venta
A10: Atributos
A11: Modificador de aceso | B11: Nombre | C11: Tipo de dato | E11: Tipo modificación atributo | F11: Tipo acceso atributo | G11: Valor por defecto | J11: Descripción atributo
C12: Tipo de dato | D12: ¿Cuál?
A13: private | B13: id | C13: long/Long | E13: no final | F13: no static | J13: Identificador único del pago
A14: private | B14: cantidad | C14: Otro | D14: BigDecimal | E14: no final | F14: no static | J14: Monto o cantidad del pago realizado
A15: private | B15: fechaPago | C15: Otro | D15: LocalDateTime | E15: no final | F15: no static | J15: Fecha y hora en que se realizó el pago
A16: private | B16: metodoPago | C16: Otro | D16: MetodoPago | E16: no final | F16: no static | J16: Método de pago utilizado para la transacción
A17: Constructores
A18: Modificador de aceso | B18: Nombre | C18: Tipo constructor | D18: Descripción | E18: Parámetros | M18: Excepciones
E19: Nombre | F19: Tipo de dato | G19: ¿Cuál? | H19: Tipo parámetro | I19: Tipo modificación atributo | J19: Descripción
A20: public | B20: =B2 -> Pago | C20: Defecto | D20: Constructor por defecto que inicializa una nueva instancia de Pago sin parámetros
A21: public | B21: =B2 -> Pago | C21: Parametrizado | D21: Constructor parametrizado que inicializa un Pago con todos sus atributos | E21: id | F21: long/Long | H21: Por valor | I21: no final | J21: Parámetro que representa el identificador único del pago
A22: public | B22: Pago | E22: cantidad | F22: Otro | G22: BigDecimal | H22: Por valor | I22: no final | J22: Parámetro que representa la cantidad del pago
A23: public | B23: Pago | E23: fechaPago | F23: Otro | G23: LocalDateTime | H23: Por valor | I23: no final | J23: Parámetro que representa la fecha y hora del pago
A24: public | B24: Pago | E24: metodoPago | F24: Otro | G24: MetodoPago | H24: Por valor | I24: no final | J24: Parámetro que representa el método de pago utilizado
A25: Métodos accesores
A26: Modificador de aceso | B26: Nombre | C26: Tipo método accesor | D26: Tipo modificación método | E26: Descripción | F26: Parámetros | L26: Tipo dato de retorno | N26: Excepciones
F27: Nombre | G27: Tipo de dato | H27: ¿Cuál? | I27: Tipo parámetro | J27: Tipo modificación atributo | K27: Descripción | L27: Tipo de dato | M27: ¿Cuál?
A28: public | B28: getId | C28: getter | D28: no final | E28: Método encargado de obtener el valor del atributo id | L28: long/Long
A29: public | B29: setId | C29: setter | D29: no final | E29: Método encargado de colocar el valor al atributo id | F29: id | G29: long/Long | I29: Por valor | J29: no final
A30: public | B30: getCantidad | C30: getter | D30: no final | E30: Método encargado de obtener el valor del atributo cantidad | L30: Otro | M30: BigDecimal
A31: public | B31: setCantidad | C31: setter | D31: no final | E31: Método encargado de colocar el valor al atributo cantidad | F31: cantidad | G31: Otro | H31: BigDecimal | I31: Por valor | J31: no final
A32: public | B32: getFechaPago | C32: getter | D32: no final | E32: Método encargado de obtener el valor del atributo fechaPago | L32: Otro | M32: LocalDateTime
A33: public | B33: setFechaPago | C33: setter | D33: no final | E33: Método encargado de colocar el valor al atributo fechaPago | F33: fechaPago | G33: Otro | H33: LocalDateTime | I33: Por valor | J33: no final
A34: public | B34: getMetodoPago | C34: getter | D34: no final | E34: Método encargado de obtener el valor del atributo metodoPago | L34: Otro | M34: MetodoPago
A35: public | B35: setMetodoPago | C35: setter | D35: no final | E35: Método encargado de colocar el valor al atributo metodoPago | F35: metodoPago | G35: Otro | H35: MetodoPago | I35: Por valor | J35: no final
A36: Métodos
A37: Modificador de aceso | B37: Nombre | C37: Tipo acceso método | D37: Tipo modificación método | E37: Descripción | F37: Parámetros | L37: Tipo dato de retorno | N37: Excepciones
F38: Nombre | G38: Tipo de dato | H38: ¿Cuál? | I38: Tipo parámetro | J38: Tipo modificación atributo | K38: Descripción | L38: Tipo de dato | M38: ¿Cuál?
A39: public | B39: aplicarAVenta | C39: no static | D39: no final | E39: Método encargado de aplicar el pago a una venta específica | F39: venta | G39: Otro | H39: Venta | I39: Por valor | J39: no final | K39: Parámetro que representa la venta a la cual se aplicará el pago | L39: void | N39: En caso de que el valor recibido por parámetro llegue vacío
A40: public | B40: esValido | C40: no static | D40: no final | E40: Método encargado de validar si el pago es válido | L40: boolean/Boolean

Sheet Produccion
A1: <-Volver al inicio
A2: =Clases!$A$1 -> Clase | B2: =Clases!A15 -> Produccion
A3: =Clases!$B$1 -> Estereotipo | B3: =Clases!B15 -> class
A4: =Clases!$C$1 -> Desripción | B4: =Clases!C15 -> Clase que representa una producción de bloques en el sistema, incluyendo información sobre la fecha, cantidad producida y detalles de producción.
A5: Modificador acceso: | B5: default
A6: Tipo clase: | B6: no final
A7: Relaciones
A8: Relación | B8: Tipo relación | E8: Estructura
A9: Necesita de | B9: Composición | E9: DetalleAbastecimiento
A10: Necesita de | B10: Composición | E10: ProduccionDetalle
A11: Es usada por | B11: Asociación | E11: Insumo
A12: Atributos
A13: Modificador de aceso | B13: Nombre | C13: Tipo de dato | E13: Tipo modificación atributo | F13: Tipo acceso atributo | G13: Valor por defecto | J13: Descripción atributo
C14: Tipo de dato | D14: ¿Cuál?
A15: private | B15: idProduccion | C15: long/Long | E15: no final | F15: no static | J15: Identificador único de la producción
A16: private | B16: fechaProduccion | C16: Otro | D16: LocalDate | E16: no final | F16: no static | J16: Fecha en que se realizó la producción
A17: Constructores
A18: Modificador de aceso | B18: Nombre | C18: Tipo constructor | D18: Descripción | E18: Parámetros | M18: Excepciones
E19: Nombre | F19: Tipo de dato | G19: ¿Cuál? | H19: Tipo parámetro | I19: Tipo modificación atributo | J19: Descripción
A20: private | B20: =B2 -> Produccion | C20: Defecto | D20: Constructor por defecto que inicializa una nueva instancia de Produccion sin parámetros
A21: public | B21: =B2 -> Produccion | C21: Parametrizado | D21: Constructor parametrizado que inicializa una Produccion con todos sus atributos | E21: idProduccion | F21: long/Long | H21: Por valor | I21: no final | J21: Parámetro que representa el identificador único de la producción
A22: public | E22: fechaProduccion | F22: Otro | G22: LocalDate | H22: Por valor | I22: no final | J22: Parámetro que representa la fecha de la producción
A23: Métodos accesores
A24: Modificador de aceso | B24: Nombre | C24: Tipo método accesor | D24: Tipo modificación método | E24: Descripción | F24: Parámetros | L24: Tipo dato de retorno | N24: Excepciones
F25: Nombre | G25: Tipo de dato | H25: ¿Cuál? | I25: Tipo parámetro | J25: Tipo modificación atributo | K25: Descripción | L25: Tipo de dato | M25: ¿Cuál?
A26: public | B26: getIdProduccion | C26: getter | D26: no final | E26: Método encargado de obtener el valor del atributo idProduccion | L26: long/Long
A27: public | B27: setIdProduccion | C27: setter | D27: no final | E27: Método encargado de colocar el valor al atributo idProduccion | F27: idProduccion | G27: short/Short | I27: Por valor | J27: no final | K27: Parámetro que representa el identificador a asignar al atributo idProduccion
A28: public | B28: getFechaProduccion | C28: getter | D28: no final | E28: Método encargado de obtener el valor del atributo fechaProduccion | L28: Otro | M28: LocalDate
A29: public | B29: setFechaProduccion | C29: setter | D29: no final | E29: Método encargado de colocar el valor al atributo fechaProduccion | F29: fechaProduccion | G29: short/Short | I29: Por valor | J29: no final | K29: Parámetro que representa la fecha a asignar al atributo fechaProduccion
A30: Métodos
